[2025-05-23T08:28:24.760+0000] {taskinstance.py:1956} INFO - Dependencies all met for dep_context=non-requeueable deps ti=<TaskInstance: exchange_rate_fetch_dag.fetch_exchange_data scheduled__2025-05-22T00:00:00+00:00 [queued]>
[2025-05-23T08:28:24.763+0000] {taskinstance.py:1956} INFO - Dependencies all met for dep_context=requeueable deps ti=<TaskInstance: exchange_rate_fetch_dag.fetch_exchange_data scheduled__2025-05-22T00:00:00+00:00 [queued]>
[2025-05-23T08:28:24.763+0000] {taskinstance.py:2170} INFO - Starting attempt 2 of 2
[2025-05-23T08:28:24.767+0000] {taskinstance.py:2191} INFO - Executing <Task(PythonOperator): fetch_exchange_data> on 2025-05-22 00:00:00+00:00
[2025-05-23T08:28:24.769+0000] {standard_task_runner.py:60} INFO - Started process 258 to run task
[2025-05-23T08:28:24.770+0000] {standard_task_runner.py:87} INFO - Running: ['***', 'tasks', 'run', 'exchange_rate_fetch_dag', 'fetch_exchange_data', 'scheduled__2025-05-22T00:00:00+00:00', '--job-id', '4', '--raw', '--subdir', 'DAGS_FOLDER/fetch_exchange_dag.py', '--cfg-path', '/tmp/tmpspbvfh0l']
[2025-05-23T08:28:24.771+0000] {standard_task_runner.py:88} INFO - Job 4: Subtask fetch_exchange_data
[2025-05-23T08:28:24.787+0000] {task_command.py:423} INFO - Running <TaskInstance: exchange_rate_fetch_dag.fetch_exchange_data scheduled__2025-05-22T00:00:00+00:00 [running]> on host e1474b1ee6d1
[2025-05-23T08:28:24.810+0000] {taskinstance.py:2480} INFO - Exporting env vars: AIRFLOW_CTX_DAG_OWNER='***' AIRFLOW_CTX_DAG_ID='exchange_rate_fetch_dag' AIRFLOW_CTX_TASK_ID='fetch_exchange_data' AIRFLOW_CTX_EXECUTION_DATE='2025-05-22T00:00:00+00:00' AIRFLOW_CTX_TRY_NUMBER='2' AIRFLOW_CTX_DAG_RUN_ID='scheduled__2025-05-22T00:00:00+00:00'
[2025-05-23T08:28:27.419+0000] {taskinstance.py:2698} ERROR - Task failed with exception
Traceback (most recent call last):
  File "/home/airflow/.local/lib/python3.8/site-packages/requests/models.py", line 971, in json
    return complexjson.loads(self.text, **kwargs)
  File "/usr/local/lib/python3.8/json/__init__.py", line 357, in loads
    return _default_decoder.decode(s)
  File "/usr/local/lib/python3.8/json/decoder.py", line 337, in decode
    obj, end = self.raw_decode(s, idx=_w(s, 0).end())
  File "/usr/local/lib/python3.8/json/decoder.py", line 355, in raw_decode
    raise JSONDecodeError("Expecting value", s, err.value) from None
json.decoder.JSONDecodeError: Expecting value: line 2 column 1 (char 1)

During handling of the above exception, another exception occurred:

Traceback (most recent call last):
  File "/home/airflow/.local/lib/python3.8/site-packages/airflow/models/taskinstance.py", line 433, in _execute_task
    result = execute_callable(context=context, **execute_callable_kwargs)
  File "/home/airflow/.local/lib/python3.8/site-packages/airflow/operators/python.py", line 199, in execute
    return_value = self.execute_callable()
  File "/home/airflow/.local/lib/python3.8/site-packages/airflow/operators/python.py", line 216, in execute_callable
    return self.python_callable(*self.op_args, **self.op_kwargs)
  File "/opt/airflow/dags/fetch_exchange_rate.py", line 16, in fetch_exchange_rate
    data = response.json()
  File "/home/airflow/.local/lib/python3.8/site-packages/requests/models.py", line 975, in json
    raise RequestsJSONDecodeError(e.msg, e.doc, e.pos)
requests.exceptions.JSONDecodeError: Expecting value: line 2 column 1 (char 1)
[2025-05-23T08:28:27.437+0000] {taskinstance.py:1138} INFO - Marking task as FAILED. dag_id=exchange_rate_fetch_dag, task_id=fetch_exchange_data, execution_date=20250522T000000, start_date=20250523T082824, end_date=20250523T082827
[2025-05-23T08:28:27.446+0000] {standard_task_runner.py:107} ERROR - Failed to execute job 4 for task fetch_exchange_data (Expecting value: line 2 column 1 (char 1); 258)
[2025-05-23T08:28:27.493+0000] {local_task_job_runner.py:234} INFO - Task exited with return code 1
[2025-05-23T08:28:27.513+0000] {taskinstance.py:3280} INFO - 0 downstream tasks scheduled from follow-on schedule check
