[2025-05-23T08:24:12.287+0000] {taskinstance.py:1956} INFO - Dependencies all met for dep_context=non-requeueable deps ti=<TaskInstance: exchange_rate_fetch_dag.fetch_exchange_data manual__2025-05-23T08:24:11.911193+00:00 [queued]>
[2025-05-23T08:24:12.290+0000] {taskinstance.py:1956} INFO - Dependencies all met for dep_context=requeueable deps ti=<TaskInstance: exchange_rate_fetch_dag.fetch_exchange_data manual__2025-05-23T08:24:11.911193+00:00 [queued]>
[2025-05-23T08:24:12.290+0000] {taskinstance.py:2170} INFO - Starting attempt 1 of 2
[2025-05-23T08:24:12.294+0000] {taskinstance.py:2191} INFO - Executing <Task(PythonOperator): fetch_exchange_data> on 2025-05-23 08:24:11.911193+00:00
[2025-05-23T08:24:12.296+0000] {standard_task_runner.py:60} INFO - Started process 216 to run task
[2025-05-23T08:24:12.297+0000] {standard_task_runner.py:87} INFO - Running: ['***', 'tasks', 'run', 'exchange_rate_fetch_dag', 'fetch_exchange_data', 'manual__2025-05-23T08:24:11.911193+00:00', '--job-id', '3', '--raw', '--subdir', 'DAGS_FOLDER/fetch_exchange_dag.py', '--cfg-path', '/tmp/tmp_lygor5u']
[2025-05-23T08:24:12.298+0000] {standard_task_runner.py:88} INFO - Job 3: Subtask fetch_exchange_data
[2025-05-23T08:24:12.314+0000] {task_command.py:423} INFO - Running <TaskInstance: exchange_rate_fetch_dag.fetch_exchange_data manual__2025-05-23T08:24:11.911193+00:00 [running]> on host e1474b1ee6d1
[2025-05-23T08:24:12.344+0000] {taskinstance.py:2480} INFO - Exporting env vars: AIRFLOW_CTX_DAG_OWNER='***' AIRFLOW_CTX_DAG_ID='exchange_rate_fetch_dag' AIRFLOW_CTX_TASK_ID='fetch_exchange_data' AIRFLOW_CTX_EXECUTION_DATE='2025-05-23T08:24:11.911193+00:00' AIRFLOW_CTX_TRY_NUMBER='1' AIRFLOW_CTX_DAG_RUN_ID='manual__2025-05-23T08:24:11.911193+00:00'
[2025-05-23T08:24:15.303+0000] {taskinstance.py:2698} ERROR - Task failed with exception
Traceback (most recent call last):
  File "/home/airflow/.local/lib/python3.8/site-packages/requests/models.py", line 971, in json
    return complexjson.loads(self.text, **kwargs)
  File "/usr/local/lib/python3.8/json/__init__.py", line 357, in loads
    return _default_decoder.decode(s)
  File "/usr/local/lib/python3.8/json/decoder.py", line 337, in decode
    obj, end = self.raw_decode(s, idx=_w(s, 0).end())
  File "/usr/local/lib/python3.8/json/decoder.py", line 355, in raw_decode
    raise JSONDecodeError("Expecting value", s, err.value) from None
json.decoder.JSONDecodeError: Expecting value: line 2 column 1 (char 1)

During handling of the above exception, another exception occurred:

Traceback (most recent call last):
  File "/home/airflow/.local/lib/python3.8/site-packages/airflow/models/taskinstance.py", line 433, in _execute_task
    result = execute_callable(context=context, **execute_callable_kwargs)
  File "/home/airflow/.local/lib/python3.8/site-packages/airflow/operators/python.py", line 199, in execute
    return_value = self.execute_callable()
  File "/home/airflow/.local/lib/python3.8/site-packages/airflow/operators/python.py", line 216, in execute_callable
    return self.python_callable(*self.op_args, **self.op_kwargs)
  File "/opt/airflow/dags/fetch_exchange_rate.py", line 16, in fetch_exchange_rate
    data = response.json()
  File "/home/airflow/.local/lib/python3.8/site-packages/requests/models.py", line 975, in json
    raise RequestsJSONDecodeError(e.msg, e.doc, e.pos)
requests.exceptions.JSONDecodeError: Expecting value: line 2 column 1 (char 1)
[2025-05-23T08:24:15.314+0000] {taskinstance.py:1138} INFO - Marking task as UP_FOR_RETRY. dag_id=exchange_rate_fetch_dag, task_id=fetch_exchange_data, execution_date=20250523T082411, start_date=20250523T082412, end_date=20250523T082415
[2025-05-23T08:24:15.323+0000] {standard_task_runner.py:107} ERROR - Failed to execute job 3 for task fetch_exchange_data (Expecting value: line 2 column 1 (char 1); 216)
[2025-05-23T08:24:15.340+0000] {local_task_job_runner.py:234} INFO - Task exited with return code 1
[2025-05-23T08:24:15.353+0000] {taskinstance.py:3280} INFO - 0 downstream tasks scheduled from follow-on schedule check
